Workbook

Sheet Resumo
A1: Telco Customer Churn — Resumo das fontes de dados
A2: EDSB 2026 · NOVA IMS · Projeto D — Retention Management
A5: Fonte | B5: Ficheiro | C5: Grão | D5: Chave de ligação | E5: Nº linhas | F5: Nº colunas | G5: Features | H5: Chaves | I5: Benchmark / priorização | J5: Excluídas (redundante, leakage, reporting)
A6: Demographics | B6: Telco_customer_churn_demographics.xlsx | C6: 1 linha por cliente | D6: Customer ID | E6: =INDEX(Dicionario_Fontes!$F$6:$F$67,MATCH(A6,Dicionario_Fontes!$A$6:$A$67,0)) -> 7043 | F6: =COUNTIF(Dicionario_Fontes!$A$6:$A$67,A6) -> 9 | G6: =COUNTIFS(Dicionario_Fontes!$A$6:$A$67,A6,Dicionario_Fontes!$P$6:$P$67,"Feature") -> 4 | H6: =COUNTIFS(Dicionario_Fontes!$A$6:$A$67,A6,Dicionario_Fontes!$P$6:$P$67,"Chave") -> 1 | I6: =COUNTIFS(Dicionario_Fontes!$A$6:$A$67,A6,Dicionario_Fontes!$P$6:$P$67,"Benchmark")+COUNTIFS(Dicionario_Fontes!$A$6:$A$67,A6,Dicionario_Fontes!$P$6:$P$67,"Priorização")+COUNTIFS(Dicionario_Fontes!$A$6:$A$67,A6,Dicionario_Fontes!$P$6:$P$67,"Suspeita*") -> 0 | J6: =F6-G6-H6-I6 -> 4
A7: Location | B7: Telco_customer_churn_location.xlsx | C7: 1 linha por cliente | D7: Customer ID | E7: =INDEX(Dicionario_Fontes!$F$6:$F$67,MATCH(A7,Dicionario_Fontes!$A$6:$A$67,0)) -> 7043 | F7: =COUNTIF(Dicionario_Fontes!$A$6:$A$67,A7) -> 9 | G7: =COUNTIFS(Dicionario_Fontes!$A$6:$A$67,A7,Dicionario_Fontes!$P$6:$P$67,"Feature") -> 2 | H7: =COUNTIFS(Dicionario_Fontes!$A$6:$A$67,A7,Dicionario_Fontes!$P$6:$P$67,"Chave") -> 2 | I7: =COUNTIFS(Dicionario_Fontes!$A$6:$A$67,A7,Dicionario_Fontes!$P$6:$P$67,"Benchmark")+COUNTIFS(Dicionario_Fontes!$A$6:$A$67,A7,Dicionario_Fontes!$P$6:$P$67,"Priorização")+COUNTIFS(Dicionario_Fontes!$A$6:$A$67,A7,Dicionario_Fontes!$P$6:$P$67,"Suspeita*") -> 0 | J7: =F7-G7-H7-I7 -> 5
A8: Population | B8: Telco_customer_churn_population.xlsx | C8: 1 linha por ZIP code | D8: Zip Code | E8: =INDEX(Dicionario_Fontes!$F$6:$F$67,MATCH(A8,Dicionario_Fontes!$A$6:$A$67,0)) -> 1671 | F8: =COUNTIF(Dicionario_Fontes!$A$6:$A$67,A8) -> 3 | G8: =COUNTIFS(Dicionario_Fontes!$A$6:$A$67,A8,Dicionario_Fontes!$P$6:$P$67,"Feature") -> 1 | H8: =COUNTIFS(Dicionario_Fontes!$A$6:$A$67,A8,Dicionario_Fontes!$P$6:$P$67,"Chave") -> 1 | I8: =COUNTIFS(Dicionario_Fontes!$A$6:$A$67,A8,Dicionario_Fontes!$P$6:$P$67,"Benchmark")+COUNTIFS(Dicionario_Fontes!$A$6:$A$67,A8,Dicionario_Fontes!$P$6:$P$67,"Priorização")+COUNTIFS(Dicionario_Fontes!$A$6:$A$67,A8,Dicionario_Fontes!$P$6:$P$67,"Suspeita*") -> 0 | J8: =F8-G8-H8-I8 -> 1
A9: Services | B9: Telco_customer_churn_services.xlsx | C9: 1 linha por cliente | D9: Customer ID | E9: =INDEX(Dicionario_Fontes!$F$6:$F$67,MATCH(A9,Dicionario_Fontes!$A$6:$A$67,0)) -> 7043 | F9: =COUNTIF(Dicionario_Fontes!$A$6:$A$67,A9) -> 30 | G9: =COUNTIFS(Dicionario_Fontes!$A$6:$A$67,A9,Dicionario_Fontes!$P$6:$P$67,"Feature") -> 25 | H9: =COUNTIFS(Dicionario_Fontes!$A$6:$A$67,A9,Dicionario_Fontes!$P$6:$P$67,"Chave") -> 1 | I9: =COUNTIFS(Dicionario_Fontes!$A$6:$A$67,A9,Dicionario_Fontes!$P$6:$P$67,"Benchmark")+COUNTIFS(Dicionario_Fontes!$A$6:$A$67,A9,Dicionario_Fontes!$P$6:$P$67,"Priorização")+COUNTIFS(Dicionario_Fontes!$A$6:$A$67,A9,Dicionario_Fontes!$P$6:$P$67,"Suspeita*") -> 0 | J9: =F9-G9-H9-I9 -> 4
A10: Status | B10: Telco_customer_churn_status.xlsx | C10: 1 linha por cliente | D10: Customer ID | E10: =INDEX(Dicionario_Fontes!$F$6:$F$67,MATCH(A10,Dicionario_Fontes!$A$6:$A$67,0)) -> 7043 | F10: =COUNTIF(Dicionario_Fontes!$A$6:$A$67,A10) -> 11 | G10: =COUNTIFS(Dicionario_Fontes!$A$6:$A$67,A10,Dicionario_Fontes!$P$6:$P$67,"Feature") -> 0 | H10: =COUNTIFS(Dicionario_Fontes!$A$6:$A$67,A10,Dicionario_Fontes!$P$6:$P$67,"Chave") -> 1 | I10: =COUNTIFS(Dicionario_Fontes!$A$6:$A$67,A10,Dicionario_Fontes!$P$6:$P$67,"Benchmark")+COUNTIFS(Dicionario_Fontes!$A$6:$A$67,A10,Dicionario_Fontes!$P$6:$P$67,"Priorização")+COUNTIFS(Dicionario_Fontes!$A$6:$A$67,A10,Dicionario_Fontes!$P$6:$P$67,"Suspeita*") -> 3 | J10: =F10-G10-H10-I10 -> 7
A11: Total | F11: =SUM(F6:F10) -> 62 | G11: =SUM(G6:G10) -> 32 | H11: =SUM(H6:H10) -> 6 | I11: =SUM(I6:I10) -> 3 | J11: =SUM(J6:J10) -> 21
A12: Nota: 'Excluídas' inclui Customer Status (origem do target) e campos removidos antes da união (Count, Quarter, ID). Customer ID e Zip Code contam como chaves em cada ficheiro.
A14: Volumes de clientes
A15: Segmento | B15: Nº clientes | C15: % do total | D15: Utilização
A16: Stayed | B16: 4720 | C16: =B16/$B$19 -> 0.67016896 | D16: População de modelação (churn = 0)
A17: Churned | B17: 1869 | C17: =B17/$B$19 -> 0.26536987 | D17: População de modelação (churn = 1)
A18: Joined | B18: 454 | C18: =B18/$B$19 -> 0.064461167 | D18: Fora do modelo; scoring posterior
A19: Total clientes | B19: =SUM(B16:B18) -> 7043 | C19: =B19/$B$19 -> 1
A20: Modelação (Churned + Stayed) | B20: =B16+B17 -> 6589 | C20: =B20/$B$19 -> 0.93553883 | D20: Base do treino/teste
A21: Taxa de churn (modelação) | B21: =B17/B20 -> 0.28365458
A22: Treino (80%, estratificado) | B22: 5271 | C22: =B22/$B$20 -> 0.79996965 | D22: % sobre a modelação
A23: Teste (20%, estratificado) | B23: =B20-B22 -> 1318 | C23: =B23/$B$20 -> 0.20003035 | D23: % sobre a modelação
A24: Fonte: contagens de Customer Status no ficheiro Status; treino calculado no pipeline (train_test_split, test_size=0,20, random_state=42).
A26: Fluxo de colunas até ao dataset final
A27: Etapa | B27: Nº colunas | C27: Detalhe
A28: Colunas nos 5 ficheiros | B28: =SUM(F6:F10) -> 62 | C28: Soma das colunas de todos os ficheiros
A29: Após união | B29: 51 | C29: Remove Count/Quarter repetidos, ID e chaves duplicadas
A30: Excluídas da modelação | B30: -15 | C30: 10 redundantes + 5 leakage
A31: Features criadas | B31: 4 | C31: n_add_on_services, has_refund, avg_hist_charge, charge_delta
A32: Target | B32: 1 | C32: churn
A33: Dataset final (train/test.csv) | B33: =SUM(B29:B32) -> 41 | C33: 1 ID + 3 negócio + 17 numéricas + 19 categóricas + target
A34: Features após one-hot | B34: 48 | C34: 17 numéricas + 15 binárias + 16 multiclasse

Sheet Dicionario_Fontes
A1: Dicionário de dados por fonte
A2: 62 colunas dos 5 ficheiros originais · estatísticas calculadas sobre todas as linhas de cada ficheiro (Python/pandas, keep_default_na=False)
A5: Fonte | B5: Coluna | C5: Descrição / o que contém | D5: Tipo de dados | E5: Tipo de variável | F5: Nº linhas | G5: Valores distintos | H5: Missing / vazios | I5: % missing | J5: Mínimo | K5: Mediana | L5: Média | M5: Máximo | N5: Categorias e frequências | O5: Exemplo | P5: Papel no projeto | Q5: Decisão no dataset final
A6: Demographics | B6: Customer ID | C6: Identificador único do cliente; chave de união entre ficheiros. | D6: Texto | E6: Identificador | F6: 7043 | G6: 7043 | H6: 0 | I6: =IFERROR(H6/F6,0) -> 0 | N6: 7.043 valores únicos (1 por linha) | O6: 8779-QRDMV | P6: Chave | Q6: Mantida apenas como chave (Customer ID)
A7: Demographics | B7: Count | C7: Campo de reporting (valor 1) para contar clientes em dashboards. | D7: Inteiro | E7: Constante | F7: 7043 | G7: 1 | H7: 0 | I7: =IFERROR(H7/F7,0) -> 0 | N7: Valor único: 1 | O7: 1 | P7: Reporting | Q7: Removida antes da união
A8: Demographics | B8: Gender | C8: Género do cliente. | D8: Texto | E8: Binária | F8: 7043 | G8: 2 | H8: 0 | I8: =IFERROR(H8/F8,0) -> 0 | N8: Male (3.555) · Female (3.488) | O8: Male | P8: Feature | Q8: Mantida → Gender_Male
A9: Demographics | B9: Age | C9: Idade em anos no fim do trimestre. | D9: Inteiro | E9: Numérica discreta | F9: 7043 | G9: 62 | H9: 0 | I9: =IFERROR(H9/F9,0) -> 0 | J9: 19 | K9: 46 | L9: 46.509726 | M9: 80 | O9: 78 | P9: Feature | Q9: Mantida
A10: Demographics | B10: Under 30 | C10: Yes se Age < 30 (derivação exata de Age). | D10: Texto | E10: Binária | F10: 7043 | G10: 2 | H10: 0 | I10: =IFERROR(H10/F10,0) -> 0 | N10: No (5.642) · Yes (1.401) | O10: No | P10: Redundante | Q10: Excluída (derivada de Age)
A11: Demographics | B11: Senior Citizen | C11: Yes se Age ≥ 65 (derivação exata de Age). | D11: Texto | E11: Binária | F11: 7043 | G11: 2 | H11: 0 | I11: =IFERROR(H11/F11,0) -> 0 | N11: No (5.901) · Yes (1.142) | O11: Yes | P11: Redundante | Q11: Excluída (derivada de Age)
A12: Demographics | B12: Married | C12: Se o cliente é casado. | D12: Texto | E12: Binária | F12: 7043 | G12: 2 | H12: 0 | I12: =IFERROR(H12/F12,0) -> 0 | N12: No (3.641) · Yes (3.402) | O12: No | P12: Feature | Q12: Mantida → Married_Yes
A13: Demographics | B13: Dependents | C13: Yes se Number of Dependents > 0 (derivação exata). | D13: Texto | E13: Binária | F13: 7043 | G13: 2 | H13: 0 | I13: =IFERROR(H13/F13,0) -> 0 | N13: No (5.416) · Yes (1.627) | O13: No | P13: Redundante | Q13: Excluída (derivada)
A14: Demographics | B14: Number of Dependents | C14: Nº de dependentes que vivem com o cliente. | D14: Inteiro | E14: Numérica discreta | F14: 7043 | G14: 10 | H14: 0 | I14: =IFERROR(H14/F14,0) -> 0 | J14: 0 | K14: 0 | L14: 0.46869232 | M14: 9 | O14: 0 | P14: Feature | Q14: Mantida
A15: Location | B15: Customer ID | C15: Identificador único do cliente; chave de união entre ficheiros. | D15: Texto | E15: Identificador | F15: 7043 | G15: 7043 | H15: 0 | I15: =IFERROR(H15/F15,0) -> 0 | N15: 7.043 valores únicos (1 por linha) | O15: 8779-QRDMV | P15: Chave | Q15: Mantida apenas como chave (Customer ID)
A16: Location | B16: Count | C16: Campo de reporting (valor 1) para contar clientes em dashboards. | D16: Inteiro | E16: Constante | F16: 7043 | G16: 1 | H16: 0 | I16: =IFERROR(H16/F16,0) -> 0 | N16: Valor único: 1 | O16: 1 | P16: Reporting | Q16: Removida antes da união
A17: Location | B17: Country | C17: País; constante United States. | D17: Texto | E17: Constante | F17: 7043 | G17: 1 | H17: 0 | I17: =IFERROR(H17/F17,0) -> 0 | N17: United States (7.043) | O17: United States | P17: Redundante | Q17: Excluída (constante)
A18: Location | B18: State | C18: Estado; constante California. | D18: Texto | E18: Constante | F18: 7043 | G18: 1 | H18: 0 | I18: =IFERROR(H18/F18,0) -> 0 | N18: California (7.043) | O18: California | P18: Redundante | Q18: Excluída (constante)
A19: Location | B19: City | C19: Cidade da residência principal. | D19: Texto | E19: Nominal (alta cardinalidade) | F19: 7043 | G19: 1106 | H19: 0 | I19: =IFERROR(H19/F19,0) -> 0 | N19: 1.106 valores distintos. Mais frequentes: Los Angeles (293) · San Diego (285) · San Jose (112) · Sacramento (108) | O19: Los Angeles | P19: Redundante | Q19: Excluída (~1.100 categorias)
A20: Location | B20: Zip Code | C20: ZIP code da residência; chave para Population. | D20: Inteiro | E20: Identificador geográfico | F20: 7043 | G20: 1626 | H20: 0 | I20: =IFERROR(H20/F20,0) -> 0 | O20: 90022 | P20: Chave | Q20: Usada para unir Population; excluída das features
A21: Location | B21: Lat Long | C21: Texto 'latitude, longitude'; duplica as colunas numéricas. | D21: Texto | E21: Texto | F21: 7043 | G21: 1679 | H21: 0 | I21: =IFERROR(H21/F21,0) -> 0 | N21: 1.679 valores distintos. Mais frequentes: 33.362575, -117.299644 (43) · 33.141265, -116.967221 (38) · 32.825086, -117.199424 (34) · 32.886925, -117.152162 (32) | O21: 34.02381, -118.156582 | P21: Redundante | Q21: Excluída (duplicada)
A22: Location | B22: Latitude | C22: Latitude da residência principal. | D22: Decimal | E22: Numérica contínua | F22: 7043 | G22: 1626 | H22: 0 | I22: =IFERROR(H22/F22,0) -> 0 | J22: 32.555828 | K22: 36.205465 | L22: 36.197455 | M22: 41.962127 | O22: 34.02381 | P22: Feature | Q22: Mantida
A23: Location | B23: Longitude | C23: Longitude da residência principal. | D23: Decimal | E23: Numérica contínua | F23: 7043 | G23: 1625 | H23: 0 | I23: =IFERROR(H23/F23,0) -> 0 | J23: -124.30137 | K23: -119.59529 | L23: -119.75668 | M23: -114.1929 | O23: -118.156582 | P23: Feature | Q23: Mantida
A24: Population | B24: ID | C24: Identificador da linha da tabela Population. | D24: Inteiro | E24: Identificador | F24: 1671 | G24: 1671 | H24: 0 | I24: =IFERROR(H24/F24,0) -> 0 | O24: 1 | P24: Reporting | Q24: Removida antes da união
A25: Population | B25: Zip Code | C25: ZIP code da residência; chave para Population. | D25: Inteiro | E25: Identificador geográfico | F25: 1671 | G25: 1671 | H25: 0 | I25: =IFERROR(H25/F25,0) -> 0 | O25: 90001 | P25: Chave | Q25: Usada para unir Population; excluída das features
A26: Population | B26: Population | C26: População estimada da área do ZIP code. | D26: Inteiro | E26: Numérica discreta | F26: 1671 | G26: 1607 | H26: 0 | I26: =IFERROR(H26/F26,0) -> 0 | J26: 11 | K26: 14239 | L26: 20276.384 | M26: 105285 | O26: 54492 | P26: Feature | Q26: Mantida (unida por Zip Code)
A27: Services | B27: Customer ID | C27: Identificador único do cliente; chave de união entre ficheiros. | D27: Texto | E27: Identificador | F27: 7043 | G27: 7043 | H27: 0 | I27: =IFERROR(H27/F27,0) -> 0 | N27: 7.043 valores únicos (1 por linha) | O27: 8779-QRDMV | P27: Chave | Q27: Mantida apenas como chave (Customer ID)
A28: Services | B28: Count | C28: Campo de reporting (valor 1) para contar clientes em dashboards. | D28: Inteiro | E28: Constante | F28: 7043 | G28: 1 | H28: 0 | I28: =IFERROR(H28/F28,0) -> 0 | N28: Valor único: 1 | O28: 1 | P28: Reporting | Q28: Removida antes da união
A29: Services | B29: Quarter | C29: Trimestre do snapshot; constante Q3, sem ano. | D29: Texto | E29: Constante | F29: 7043 | G29: 1 | H29: 0 | I29: =IFERROR(H29/F29,0) -> 0 | N29: Q3 (7.043) | O29: Q3 | P29: Reporting | Q29: Removida antes da união
A30: Services | B30: Referred a Friend | C30: Yes se Number of Referrals > 0 (derivação exata). | D30: Texto | E30: Binária | F30: 7043 | G30: 2 | H30: 0 | I30: =IFERROR(H30/F30,0) -> 0 | N30: No (3.821) · Yes (3.222) | O30: No | P30: Redundante | Q30: Excluída (derivada)
A31: Services | B31: Number of Referrals | C31: Nº de referências feitas pelo cliente até à data. | D31: Inteiro | E31: Numérica discreta | F31: 7043 | G31: 12 | H31: 0 | I31: =IFERROR(H31/F31,0) -> 0 | J31: 0 | K31: 0 | L31: 1.9518671 | M31: 11 | O31: 0 | P31: Feature | Q31: Mantida
A32: Services | B32: Tenure in Months | C32: Meses de relação com a empresa no fim do trimestre. | D32: Inteiro | E32: Numérica discreta | F32: 7043 | G32: 72 | H32: 0 | I32: =IFERROR(H32/F32,0) -> 0 | J32: 1 | K32: 29 | L32: 32.386767 | M32: 72 | O32: 1 | P32: Feature | Q32: Mantida
A33: Services | B33: Offer | C33: Última oferta aceite; 'None' = sem oferta (valor real). | D33: Texto | E33: Nominal | F33: 7043 | G33: 6 | H33: 0 | I33: =IFERROR(H33/F33,0) -> 0 | N33: None (3.877) · Offer B (824) · Offer E (805) · Offer D (602) · Offer A (520) · Offer C (415) | O33: None | P33: Feature | Q33: Mantida → 6 colunas one-hot
A34: Services | B34: Phone Service | C34: Subscreve telefone fixo. | D34: Texto | E34: Binária | F34: 7043 | G34: 2 | H34: 0 | I34: =IFERROR(H34/F34,0) -> 0 | N34: Yes (6.361) · No (682) | O34: No | P34: Feature | Q34: Mantida → Phone Service_Yes
A35: Services | B35: Avg Monthly Long Distance Charges | C35: Média mensal de encargos de longa distância. | D35: Decimal | E35: Numérica contínua | F35: 7043 | G35: 3584 | H35: 0 | I35: =IFERROR(H35/F35,0) -> 0 | J35: 0 | K35: 22.89 | L35: 22.958954 | M35: 49.99 | O35: 0.0 | P35: Feature | Q35: Mantida
A36: Services | B36: Multiple Lines | C36: Subscreve várias linhas telefónicas. | D36: Texto | E36: Binária | F36: 7043 | G36: 2 | H36: 0 | I36: =IFERROR(H36/F36,0) -> 0 | N36: No (4.072) · Yes (2.971) | O36: No | P36: Feature | Q36: Mantida → Multiple Lines_Yes
A37: Services | B37: Internet Service | C37: Subscreve internet (flag, não a tecnologia). | D37: Texto | E37: Binária | F37: 7043 | G37: 2 | H37: 0 | I37: =IFERROR(H37/F37,0) -> 0 | N37: Yes (5.517) · No (1.526) | O37: Yes | P37: Feature | Q37: Mantida → Internet Service_Yes
A38: Services | B38: Internet Type | C38: Tecnologia: Fiber Optic, DSL, Cable ou 'None' (sem internet). | D38: Texto | E38: Nominal | F38: 7043 | G38: 4 | H38: 0 | I38: =IFERROR(H38/F38,0) -> 0 | N38: Fiber Optic (3.035) · DSL (1.652) · None (1.526) · Cable (830) | O38: DSL | P38: Feature | Q38: Mantida → 4 colunas one-hot
A39: Services | B39: Avg Monthly GB Download | C39: Média mensal de GB descarregados. | D39: Inteiro | E39: Numérica discreta | F39: 7043 | G39: 50 | H39: 0 | I39: =IFERROR(H39/F39,0) -> 0 | J39: 0 | K39: 17 | L39: 20.515405 | M39: 85 | O39: 8 | P39: Feature | Q39: Mantida
A40: Services | B40: Online Security | C40: Subscreve segurança online adicional. | D40: Texto | E40: Binária | F40: 7043 | G40: 2 | H40: 0 | I40: =IFERROR(H40/F40,0) -> 0 | N40: No (5.024) · Yes (2.019) | O40: No | P40: Feature | Q40: Mantida → _Yes
A41: Services | B41: Online Backup | C41: Subscreve backup online adicional. | D41: Texto | E41: Binária | F41: 7043 | G41: 2 | H41: 0 | I41: =IFERROR(H41/F41,0) -> 0 | N41: No (4.614) · Yes (2.429) | O41: No | P41: Feature | Q41: Mantida → _Yes
A42: Services | B42: Device Protection Plan | C42: Subscreve plano de proteção de equipamento. | D42: Texto | E42: Binária | F42: 7043 | G42: 2 | H42: 0 | I42: =IFERROR(H42/F42,0) -> 0 | N42: No (4.621) · Yes (2.422) | O42: Yes | P42: Feature | Q42: Mantida → _Yes
...

Sheet Dataset_Final
A1: Dataset final — 41 colunas (train.csv / test.csv)
A2: Estatísticas sobre a população de modelação (6.589 clientes) · tratamento aplicado no ColumnTransformer
A5: # | B5: Coluna | C5: Fonte | D5: Grupo | E5: Tipo | F5: Descrição | G5: Valores (modelação) | H5: Tratamento | I5: Saída após encoding | J5: Observações
A6: 1 | B6: Customer ID | C6: Todas | D6: Identificação | E6: Texto | F6: Identificador único do cliente (chave de união dos ficheiros). | G6: 7.043 valores únicos (6.589 na modelação) | H6: Chave — excluída das features | I6: — | J6: Não entra no modelo. Permite ligar previsões ao cliente.
A7: 2 | B7: CLTV | C7: Status | D7: Negócio | E7: Inteira | F7: Valor de vida do cliente previsto por fórmulas corporativas. | G7: min 2.003 · mediana 4.552 · máx 6.500 | H7: Mantida nos CSV, fora das features | I7: — | J7: Não é feature: usado na priorização P(churn) × CLTV.
A8: 3 | B8: Churn Score | C8: Status | D8: Negócio | E8: Inteira | F8: Score 0–100 do modelo IBM SPSS existente; mais alto = maior risco. | G8: min 5 · mediana 63 · máx 96 | H8: Mantida nos CSV, fora das features | I8: — | J8: Benchmark: AUC 0,941 no holdout. Não é feature.
A9: 4 | B9: Satisfaction Score | C9: Status | D9: Negócio | E9: Inteira | F9: Satisfação global de 1 (muito insatisfeito) a 5 (muito satisfeito). | G9: min 1 · mediana 3 · máx 5 | H9: Mantida nos CSV, fora das features | I9: — | J9: Suspeita de leakage (1–2 ⇒ 100% churn). Testar com e sem.
A10: 5 | B10: Age | C10: Demographics | D10: Numérica | E10: Inteira | F10: Idade do cliente em anos no fim do trimestre. | G10: min 19 · mediana 46 · máx 80 | H10: Imputação pela mediana · árvores: valor original · linear: + StandardScaler | I10: Age | J10: Substitui Under 30 e Senior Citizen (derivadas).
A11: 6 | B11: Number of Dependents | C11: Demographics | D11: Numérica | E11: Inteira | F11: Nº de dependentes que vivem com o cliente. | G11: min 0 · mediana 0 · máx 9 | H11: Imputação pela mediana · árvores: valor original · linear: + StandardScaler | I11: Number of Dependents | J11: Substitui Dependents (derivada). Muitos zeros.
A12: 7 | B12: Latitude | C12: Location | D12: Numérica | E12: Contínua | F12: Latitude da residência principal. | G12: min 32,56 · mediana 36,25 · máx 41,96 | H12: Imputação pela mediana · árvores: valor original · linear: + StandardScaler | I12: Latitude | J12: Representa a geografia em vez de City/Zip Code.
A13: 8 | B13: Longitude | C13: Location | D13: Numérica | E13: Contínua | F13: Longitude da residência principal. | G13: min -124,30 · mediana -119,60 · máx -114,19 | H13: Imputação pela mediana · árvores: valor original · linear: + StandardScaler | I13: Longitude | J13: Correlação −0,87 com Latitude (forma da Califórnia).
A14: 9 | B14: Population | C14: Population | D14: Numérica | E14: Inteira | F14: População estimada da área do ZIP code do cliente. | G14: min 11 · mediana 17.372 · máx 105.285 | H14: Imputação pela mediana · árvores: valor original · linear: + StandardScaler | I14: Population | J14: Unida por Zip Code (N:1). Cobertura 100%.
A15: 10 | B15: Number of Referrals | C15: Services | D15: Numérica | E15: Inteira | F15: Nº de amigos referenciados pelo cliente até à data. | G15: min 0 · mediana 0 · máx 11 | H15: Imputação pela mediana · árvores: valor original · linear: + StandardScaler | I15: Number of Referrals | J15: Substitui Referred a Friend (derivada).
A16: 11 | B16: Tenure in Months | C16: Services | D16: Numérica | E16: Inteira | F16: Meses de relação com a empresa no fim do trimestre. | G16: min 1 · mediana 32 · máx 72 | H16: Imputação pela mediana · árvores: valor original · linear: + StandardScaler | I16: Tenure in Months | J16: Maior Mutual Information com o churn. ρ = 0,87 com Total Charges.
A17: 12 | B17: Avg Monthly Long Distance Charges | C17: Services | D17: Numérica | E17: Contínua | F17: Média mensal de encargos de chamadas de longa distância. | G17: min 0 · mediana 22,92 · máx 49,99 | H17: Imputação pela mediana · árvores: valor original · linear: + StandardScaler | I17: Avg Monthly Long Distance Charges | J17: 0 para clientes sem telefone.
A18: 13 | B18: Avg Monthly GB Download | C18: Services | D18: Numérica | E18: Inteira | F18: Média mensal de GB descarregados. | G18: min 0 · mediana 17 · máx 85 | H18: Imputação pela mediana · árvores: valor original · linear: + StandardScaler | I18: Avg Monthly GB Download | J18: 0 para clientes sem internet.
A19: 14 | B19: Monthly Charge | C19: Services | D19: Numérica | E19: Contínua | F19: Fatura mensal atual de todos os serviços. | G19: min 18,25 · mediana 72,85 · máx 118,75 | H19: Imputação pela mediana · árvores: valor original · linear: + StandardScaler | I19: Monthly Charge
A20: 15 | B20: Total Charges | C20: Services | D20: Numérica | E20: Contínua | F20: Encargos acumulados até ao fim do trimestre. | G20: min 18,85 · mediana 1.564 · máx 8.685 | H20: Imputação pela mediana · árvores: valor original · linear: + StandardScaler | I20: Total Charges | J20: Cumulativa: cresce com a antiguidade.
A21: 16 | B21: Total Refunds | C21: Services | D21: Numérica | E21: Contínua | F21: Reembolsos acumulados até ao fim do trimestre. | G21: min 0 · mediana 0 · máx 49,79 | H21: Imputação pela mediana · árvores: valor original · linear: + StandardScaler | I21: Total Refunds | J21: Inflacionada de zeros → criada has_refund.
A22: 17 | B22: Total Extra Data Charges | C22: Services | D22: Numérica | E22: Inteira | F22: Encargos acumulados por dados extra. | G22: min 0 · mediana 0 · máx 150 | H22: Imputação pela mediana · árvores: valor original · linear: + StandardScaler | I22: Total Extra Data Charges | J22: Inflacionada de zeros.
A23: 18 | B23: Total Long Distance Charges | C23: Services | D23: Numérica | E23: Contínua | F23: Encargos acumulados de longa distância acima do plano. | G23: min 0 · mediana 472,68 · máx 3.565 | H23: Imputação pela mediana · árvores: valor original · linear: + StandardScaler | I23: Total Long Distance Charges | J23: Cumulativa.
A24: 19 | B24: n_add_on_services | C24: Feature engineering | D24: Numérica criada | E24: Inteira | F24: Nº de serviços adicionais subscritos (0–8): segurança, backup, proteção, suporte, 3 streamings, dados ilimitados. | G24: min 0 · mediana 3 · máx 8 | H24: Imputação pela mediana · árvores: valor original · linear: + StandardScaler | I24: n_add_on_services | J24: Proxy de envolvimento com a operadora.
A25: 20 | B25: avg_hist_charge | C25: Feature engineering | D25: Numérica criada | E25: Contínua | F25: Fatura média histórica: Total Charges ÷ Tenure in Months. | G25: min 13,83 · mediana 72,25 · máx 121,40 | H25: Imputação pela mediana · árvores: valor original · linear: + StandardScaler | I25: avg_hist_charge | J25: Tenure com mínimo de 1 para evitar divisão por zero.
A26: 21 | B26: charge_delta | C26: Feature engineering | D26: Numérica criada | E26: Contínua | F26: Monthly Charge − avg_hist_charge. | G26: min -18,90 · mediana 0 · máx 19,13 | H26: Imputação pela mediana · árvores: valor original · linear: + StandardScaler | I26: charge_delta | J26: Positivo ≈ aumento de preço recente.
A27: 22 | B27: Gender | C27: Demographics | D27: Categórica | E27: Binária | F27: Género do cliente. | G27: Male 50% · Female 50% | H27: One-hot (drop='if_binary') → 1 coluna | I27: Gender_Male | J27: Cramér's V ≈ 0: sem associação com o churn.
A28: 23 | B28: Married | C28: Demographics | D28: Categórica | E28: Binária | F28: Se o cliente é casado. | G28: Yes 50% · No 50% | H28: One-hot (drop='if_binary') → 1 coluna | I28: Married_Yes | J28: Não casados: ~37% churn vs ~20% casados.
A29: 24 | B29: Offer | C29: Services | D29: Categórica | E29: Nominal (6) | F29: Última oferta aceite. 'None' é um valor real (sem oferta). | G29: None 55% · Offer B 12% · Offer E 10% · Offer D 9% · Offer A 8% · Offer C 6% | H29: One-hot → 6 colunas (uma por categoria) | I29: Offer_<categoria> ×6 | J29: Offer E ~68% churn. Preservar 'None' na leitura (keep_default_na=False).
A30: 25 | B30: Phone Service | C30: Services | D30: Categórica | E30: Binária | F30: Subscreve serviço de telefone fixo. | G30: Yes 90% · No 10% | H30: One-hot (drop='if_binary') → 1 coluna | I30: Phone Service_Yes | J30: 90% Yes: pouca variabilidade.
A31: 26 | B31: Multiple Lines | C31: Services | D31: Categórica | E31: Binária | F31: Subscreve várias linhas telefónicas. | G31: No 56% · Yes 44% | H31: One-hot (drop='if_binary') → 1 coluna | I31: Multiple Lines_Yes
A32: 27 | B32: Internet Service | C32: Services | D32: Categórica | E32: Binária | F32: Subscreve internet (flag, não é a tecnologia). | G32: Yes 80% · No 20% | H32: One-hot (drop='if_binary') → 1 coluna | I32: Internet Service_Yes | J32: No ⇔ Internet Type = None.
A33: 28 | B33: Internet Type | C33: Services | D33: Categórica | E33: Nominal (4) | F33: Tecnologia de ligação. 'None' = sem internet. | G33: Fiber Optic 44% · DSL 23% · None 20% · Cable 12% | H33: One-hot → 4 colunas (uma por categoria) | I33: Internet Type_<categoria> ×4 | J33: Fiber Optic ~42% churn; sem internet ~8%. Cramér's V ≈ 0,30.
A34: 29 | B34: Online Security | C34: Services | D34: Categórica | E34: Binária | F34: Subscreve segurança online adicional. | G34: No 70% · Yes 30% | H34: One-hot (drop='if_binary') → 1 coluna | I34: Online Security_Yes
A35: 30 | B35: Online Backup | C35: Services | D35: Categórica | E35: Binária | F35: Subscreve backup online adicional. | G35: No 64% · Yes 36% | H35: One-hot (drop='if_binary') → 1 coluna | I35: Online Backup_Yes
A36: 31 | B36: Device Protection Plan | C36: Services | D36: Categórica | E36: Binária | F36: Subscreve plano de proteção de equipamento. | G36: No 64% · Yes 36% | H36: One-hot (drop='if_binary') → 1 coluna | I36: Device Protection Plan_Yes
A37: 32 | B37: Premium Tech Support | C37: Services | D37: Categórica | E37: Binária | F37: Subscreve suporte técnico premium. | G37: No 70% · Yes 30% | H37: One-hot (drop='if_binary') → 1 coluna | I37: Premium Tech Support_Yes
A38: 33 | B38: Streaming TV | C38: Services | D38: Categórica | E38: Binária | F38: Usa a internet para streaming de TV de terceiros. | G38: No 60% · Yes 40% | H38: One-hot (drop='if_binary') → 1 coluna | I38: Streaming TV_Yes
A39: 34 | B39: Streaming Movies | C39: Services | D39: Categórica | E39: Binária | F39: Usa a internet para streaming de filmes de terceiros. | G39: No 59% · Yes 41% | H39: One-hot (drop='if_binary') → 1 coluna | I39: Streaming Movies_Yes
A40: 35 | B40: Streaming Music | C40: Services | D40: Categórica | E40: Binária | F40: Usa a internet para streaming de música de terceiros. | G40: No 63% · Yes 37% | H40: One-hot (drop='if_binary') → 1 coluna | I40: Streaming Music_Yes
A41: 36 | B41: Unlimited Data | C41: Services | D41: Categórica | E41: Binária | F41: Paga dados ilimitados. | G41: Yes 69% · No 31% | H41: One-hot (drop='if_binary') → 1 coluna | I41: Unlimited Data_Yes
A42: 37 | B42: Contract | C42: Services | D42: Categórica | E42: Ordinal (3) | F42: Tipo de contrato atual. | G42: Month-to-Month 49% · Two Year 28% · One Year 23% | H42: One-hot → 3 colunas (uma por categoria) | I42: Contract_<categoria> ×3 | J42: Associação mais forte (V ≈ 0,51): Month-to-Month ~52% churn vs ~3% Two Year.
...

Sheet Colunas_Excluidas
A1: Colunas que não chegam ao dataset final
A2: 18 campos originais e a justificação de cada exclusão
A5: Coluna | B5: Motivo | C5: Justificação
A6: Count | B6: Reporting | C6: Removida antes da união: campo de contagem para dashboards.
A7: Quarter | B7: Reporting | C7: Removida antes da união: constante Q3.
A8: ID (Population) | B8: Reporting | C8: Removida antes da união: identificador da linha da tabela Population.
A9: Country | B9: Redundante | C9: Constante (United States).
A10: State | B10: Redundante | C10: Constante (California).
A11: Lat Long | B11: Redundante | C11: Texto que duplica Latitude e Longitude.
A12: City | B12: Redundante | C12: ~1.100 categorias; ruído no one-hot. Testar com TargetEncoder no Pipeline.
A13: Zip Code | B13: Redundante | C13: Identificador geográfico; usado só para unir Population.
A14: Under 30 | B14: Redundante | C14: Derivada exata de Age (< 30).
A15: Senior Citizen | B15: Redundante | C15: Derivada exata de Age (≥ 65).
A16: Dependents | B16: Redundante | C16: Derivada exata de Number of Dependents (> 0).
... A23: Churn Reason | B23: Leakage | C23: Só existe para quem saiu (pós-churn).

Sheet Legenda
A1: Legenda dos campos e tipos de variável
A2: Como ler as folhas deste ficheiro
A5: Termo | B5: Significado
A6: Tipo de dados | B6: Formato técnico lido pelo pandas: Inteiro, Decimal ou Texto.
A7: Numérica contínua | B7: Valores reais num intervalo (ex.: Monthly Charge, Latitude).
A8: Numérica discreta | B8: Contagens ou inteiros (ex.: Tenure in Months, Number of Referrals).
A9: Binária | B9: Duas categorias (Yes/No, Male/Female, 0/1). Gera 1 coluna no one-hot.
A10: Nominal | B10: Categorias sem ordem (ex.: Payment Method). Gera 1 coluna por categoria.
A11: Ordinal | B11: Categorias com ordem natural (ex.: Contract, Satisfaction Score).
A12: Constante | B12: O mesmo valor em todas as linhas: sem informação para o modelo.
A13: Identificador / Chave | B13: Serve para ligar tabelas; não é característica do cliente.
A14: Missing / vazios | B14: Células vazias ou NaN. 'None' em Offer/Internet Type não conta como missing.
A15: Feature | B15: Entra no modelo como variável explicativa.
A16: Redundante | B16: Constante, duplicada ou derivação exata de outra coluna.
... A21: Cores | B21: Azul = cabeçalhos e numéricas · verde = categóricas/features · amarelo = target ou suspeita · rosa = leakage · cinzento = redundante/reporting.
